Workbook

Sheet HOME
E6: Comparison of TB treatment regimen prices in USD 2019 vs 2018
E9: TB treatment regimen | G9: Weight band | H9: Weighted average Prices, USD | J9: Difference in % | K9: Cheapest Prices, USD | M9: Difference in %
H10: 2018 | I10: 2019 | K10: 2018 | L10: 2019
E11: Adult Drug-Susceptible TB | F11: 2RHZE(150/75/400/275)/ 4RH(150/75) | G11: 25-39 kg | H11: ='SusceptibleTBAdult av 25-39 AV'!I15 -> 15.672 | I11: ='SusceptibleTBAdult av 25-39 AV'!T15 -> 17.786657 | J11: =(I11/H11)-1 -> 0.13493218 | K11: ='SuscTBAdult av 25-39 Cheapest'!I15 -> 14.208 | L11: ='SuscTBAdult av 25-39 Cheapest'!T15 -> 15.6 | M11: =(L11/K11)-1 -> 0.097972973
G12: 40-54 kg | H12: ='SusceptibleTBAdult av 40-54 AV'!I15 -> 23.508 | I12: ='SusceptibleTBAdult av 40-54 AV'!T15 -> 26.679986 | J12: =(I12/H12)-1 -> 0.13493218 | K12: ='SuscTBAdult av 40-54 Cheapest'!I15 -> 21.312 | L12: ='SuscTBAdult av 40-54 Cheapest'!T15 -> 23.4 | M12: =(L12/K12)-1 -> 0.097972973
G13: 55-70 kg | H13: ='SusceptibleTBAdult av 55-70 AV'!I15 -> 31.344 | I13: ='SusceptibleTBAdult av 55-70 AV'!T15 -> 35.573314 | J13: =(I13/H13)-1 -> 0.13493218 | K13: ='SuscTBAdult av 55-70 Cheapest'!I15 -> 28.416 | L13: ='SuscTBAdult av 55-70 Cheapest'!T15 -> 31.2 | M13: =(L13/K13)-1 -> 0.097972973
G14: > 70 kg | H14: ='SusceptibleTBAdult av > 70 AV'!I15 -> 39.18 | I14: ='SusceptibleTBAdult av > 70 AV'!T15 -> 44.466643 | J14: =(I14/H14)-1 -> 0.13493218 | K14: ='SusceptibleTBAdult av>70 Cheape'!I15 -> 35.52 | L14: ='SusceptibleTBAdult av>70 Cheape'!T15 -> 39 | M14: =(L14/K14)-1 -> 0.097972973
E15: Paediatric Drug-Susceptible TB | F15: 2RHZ (75/50/150)/ 4RH (75/50) | G15: 4-7 kg | H15: ='SusceptibleTBavPaed 4-7 AV'!I15 -> 6.426 | I15: ='SusceptibleTBavPaed 4-7 AV'!T15 -> 6.7828571 | J15: =(I15/H15)-1 -> 0.055533324 | K15: =H15 -> 6.426 | L15: =I15 -> 6.7828571 | M15: =(L15/K15)-1 -> 0.055533324
G16: 8-11 kg | H16: ='SusceptibleTBavPaed 8-11 AV'!I15 -> 12.857143 | I16: ='SusceptibleTBavPaed 8-11 AV'!T15 -> 13.565714 | J16: =(I16/H16)-1 -> 0.055111111 | K16: =H16 -> 12.857143 | L16: =I16 -> 13.565714 | M16: =(L16/K16)-1 -> 0.055111111
G17: 12-15 kg | H17: ='SusceptibleTBavPaed 12-15 AV'!I15 -> 19.285714 | I17: ='SusceptibleTBavPaed 12-15 AV'!T15 -> 20.348571 | J17: =(I17/H17)-1 -> 0.055111111 | K17: =H17 -> 19.285714 | L17: =I17 -> 20.348571 | M17: =(L17/K17)-1 -> 0.055111111
G18: 16-24 kg | H18: ='SusceptibleTBavPaed 16-24 AV'!I15 -> 25.714286 | I18: ='SusceptibleTBavPaed 16-24 AV'!T15 -> 27.131429 | J18: =(I18/H18)-1 -> 0.055111111 | K18: =H18 -> 25.714286 | L18: =I18 -> 27.131429 | M18: =(L18/K18)-1 -> 0.055111111
E19: MDR-TB Conventional | F19: 8 Z Km Lfx Eto Cs / 12 Z Lfx Eto Cs | G19: 46-55 kg | H19: ='Old LTR Km Eto'!I22 -> 777.876 | I19: ='Old LTR Km Eto'!T22 -> 741.96086 | J19: =(I19/H19)-1 -> -0.046170782 | K19: ='Old LTR Km Eto cheapest'!I22 -> 736.02 | L19: ='Old LTR Km Eto cheapest'!T22 -> 709.68 | M19: =(L19/K19)-1 -> -0.035787071
E20: STR MDR-TB | F20: 4 Km Cfz E H Mfx Pto Z / 5 Cfz E Mfx Z | G20: 30-50 kg | H20: ='Old STR 30-50'!I24 -> 561.7167 | I20: ='Old STR 30-50'!T24 -> 406.10273 | J20: =(I20/H20)-1 -> -0.27703283 | K20: ='STR 30-50 Cheapest'!I24 -> 538.9995 | L20: ='STR 30-50 Cheapest'!T24 -> 364.61643 | M20: =(L20/K20)-1 -> -0.32353104
E21: New LTR Mfx 6 Lnz | F21: 6 Mfx Bdq Lnz Cs Cfz / 14 Mfx Cs Cfz | G21: 46-55 kg | H21: ='New LTR Mfx 6 Lnz'!I15 -> 1860.772 | I21: ='New LTR Mfx 6 Lnz'!T15 -> 1433.7289 | J21: =(I21/H21)-1 -> -0.22949781
E22: New LTR Mfx 12 Lnz | F22: 6 Mfx Bdq Lnz Cs Cfz / 6 Mfx Lnz Cs Cfz / 8 Mfx Cs Cfz | G22: 46-55 kg | H22: ='New LTR Mfx 12 Lnz'!I15 -> 2103.664 | I22: ='New LTR Mfx 12 Lnz'!T15 -> 1558.3168 | J22: =(I22/H22)-1 -> -0.25923684
E23: New LTR Lfx 6 Lnz | F23: 6 Lfx Bdq Lnz Cs Cfz / 14 Lfx Cs Cfz | G23: 46-55 kg | H23: ='New LTR Lfx 6 Lnz'!I15 -> 1610.572 | I23: ='New LTR Lfx 6 Lnz'!T15 -> 1369.5679 | J23: =(I23/H23)-1 -> -0.14963882
E24: New LTR Lfx 12 Lnz | F24: 6 Lfx Bdq Lnz Cs Cfz / 6 Lfx Lnz Cs Cfz / 8 Lfx Cs Cfz | G24: 46-55 kg | H24: ='New LTR Lfx 12 Lnz'!I15 -> 1853.464 | I24: ='New LTR Lfx 12 Lnz'!T15 -> 1494.1558 | J24: =(I24/H24)-1 -> -0.19385766
E25: New STR Am | F25: 4 Am Cfz E H Mfx Pto Z / 5 Cfz E Mfx Z | G25: 30-50 kg | H25: ='New STR 30-50 Am'!I24 -> 620.5167 | I25: ='New STR 30-50 Am'!T24 -> 484.03073 | J25: =(I25/H25)-1 -> -0.21995535
E26: New STR BDQ | F26: 4 BDQ Cfz E H Mfx Pto Z / 5 Cfz E Mfx Z | G26: 30-50 kg | H26: ='New STR 30-50 BDQ'!I24 -> 851.3167 | I26: ='New STR 30-50 BDQ'!T24 -> 726.06273 | J26: =(I26/H26)-1 -> -0.1471297
E27: New LTR Kids | F27: 6 Lfx Cs Cfz Dlm Pas / 6 Lfx Cs Cfz Pas | G27: 10-15 kg | H27: ='New LTR Kids'!I16 -> 2277.1303 | I27: ='New LTR Kids'!T16 -> 1834.5463 | J27: =(I27/H27)-1 -> -0.19436042
E28: Modified STR | F28: 4 Lzd H BDQ Mfx Cfz E Z / 2 BDQ Mfx Cfz E Z / 3 Mfx Cfz E Z | G28: 46-55 kg | I28: ='Mod STR'!T33 -> 731.51949 | J28: N/A

Sheet SusceptibleTBavPaed 4-7 AV
B2: 2018 | M2: 2019
B3: Treatment regimen: 2RHZ(75/50/150)/4RH(75/50) | M3: Treatment regimen: 2RHZ(75/50/150)/4RH(75/50)
B4: 4-7 kg weight band | M4: 4-7 kg weight band
B6: Intensive Phase | M6: Intensive Phase
B7: Medicine | C7: Strength | D7: Cost per tablet | E7: Daily Dose in tablet | F7: Days in Months | G7: No. of months | H7: Full treatment / Number of tablets required | I7: Cost of Intensive Phase in US$ | M7: Medicine | N7: Strength | O7: Cost per tablet | P7: Daily Dose in tablet | Q7: Days in Months | R7: No. of months | S7: Full treatment / Number of tablets required | T7: Cost of Intensive Phase in US$
B8: RHZ (75/50/150) | C8: 275 mg | D8: =0.0405 -> 0.0405 | E8: 1 | F8: 30 | G8: 2 | H8: =E8*F8*G8 -> 60 | I8: =D8*H8 -> 2.43 | M8: RHZ (75/50/150) | N8: 275 mg | O8: 0.042857143 | P8: 1 | Q8: 30 | R8: 2 | S8: =P8*Q8*R8 -> 60 | T8: =O8*S8 -> 2.5714286
H9: Total Cost (USD) of Intensive Phase | I9: =SUM(I8:I8) -> 2.43 | S9: Total Cost (USD) of Intensive Phase | T9: =SUM(T8:T8) -> 2.5714286
B10: Continuation Phase | M10: Continuation Phase
B11: Medicine | C11: Strength | D11: Cost per tablet | E11: Daily Dose in tablet | F11: Days in Months | G11: No. of months | H11: Full treatment in BUC / Number of tablets required | I11: Cost of Cont Phase in US$ | M11: Medicine | N11: Strength | O11: Cost per tablet | P11: Daily Dose in tablet | Q11: Days in Months | R11: No. of months | S11: Full treatment / Number of tablets required | T11: Cost of Cont Phase in US$
B12: RH(75/50) | C12: 125 mg | D12: =0.0333 -> 0.0333 | E12: 1 | F12: 30 | G12: 4 | H12: =E12*F12*G12 -> 120 | I12: =D12*H12 -> 3.996 | M12: RH(75/50) | N12: 125 mg | O12: 0.035095238 | P12: 1 | Q12: 30 | R12: 4 | S12: =P12*Q12*R12 -> 120 | T12: =O12*S12 -> 4.2114286
H13: Total Cost (USD) of Continuation Phase | I13: =SUM(I12:I12) -> 3.996 | S13: Total Cost (USD) of Continuation Phase | T13: =SUM(T12:T12) -> 4.2114286
H15: TOTAL COST PER PATIENT FOR 6 months: | I15: =I9+I13 -> 6.426 | S15: TOTAL COST PER PATIENT FOR 6 months: | T15: =T9+T13 -> 6.7828571

Sheet SusceptibleTBavPaed 8-11 AV
B2: 2018 | M2: 2019
B3: Treatment regimen: 2RHZ(75/50/150)/4RH(75/50) | M3: Treatment regimen: 2RHZ(75/50/150)/4RH(75/50)
B4: 8-11 kg weight band | M4: 8-11 kg weight band
B6: Intensive Phase | M6: Intensive Phase
B7: Medicine | C7: Strength | D7: Cost per tablet | E7: Daily Dose in tablet | F7: Days in Months | G7: No. of months | H7: Full treatment / Number of tablets required | I7: Cost of Intensive Phase in US$ | M7: Medicine | N7: Strength | O7: Cost per tablet | P7: Daily Dose in tablet | Q7: Days in Months | R7: No. of months | S7: Full treatment / Number of tablets required | T7: Cost of Intensive Phase in US$
B8: RHZ (75/50/150) | C8: 275 mg | D8: =3.4/84 -> 0.04047619 | E8: 2 | F8: 30 | G8: 2 | H8: =E8*F8*G8 -> 120 | I8: =D8*H8 -> 4.8571429 | M8: RHZ (75/50/150) | N8: 275 mg | O8: 0.042857143 | P8: 2 | Q8: 30 | R8: 2 | S8: =P8*Q8*R8 -> 120 | T8: =O8*S8 -> 5.1428571
H9: Total Cost (USD) of Intensive Phase | I9: =SUM(I8:I8) -> 4.8571429 | S9: Total Cost (USD) of Intensive Phase | T9: =SUM(T8:T8) -> 5.1428571
B10: Continuation Phase | M10: Continuation Phase
B11: Medicine | C11: Strength | D11: Cost per tablet | E11: Daily Dose in tablet | F11: Days in Months | G11: No. of months | H11: Full treatment / Number of tablets required | I11: Cost of Cont Phase in US$ | M11: Medicine | N11: Strength | O11: Cost per tablet | P11: Daily Dose in tablet | Q11: Days in Months | R11: No. of months | S11: Full treatment / Number of tablets required | T11: Cost of Cont Phase in US$
B12: RH(75/50) | C12: 125 mg | D12: =2.8/84 -> 0.033333333 | E12: 2 | F12: 30 | G12: 4 | H12: =E12*F12*G12 -> 240 | I12: =D12*H12 -> 8 | M12: RH(75/50) | N12: 125 mg | O12: 0.035095238 | P12: 2 | Q12: 30 | R12: 4 | S12: =P12*Q12*R12 -> 240 | T12: =O12*S12 -> 8.4228571
H13: Total Cost (USD) of Continuation Phase | I13: =SUM(I12:I12) -> 8 | S13: Total Cost (USD) of Continuation Phase | T13: =SUM(T12:T12) -> 8.4228571
H15: TOTAL COST PER PATIENT FOR 6 months: | I15: =I9+I13 -> 12.857143 | S15: TOTAL COST PER PATIENT FOR 6 months: | T15: =T9+T13 -> 13.565714

Sheet SusceptibleTBavPaed 12-15 AV
B2: 2018 | M2: 2019
B3: Treatment regimen: 2RHZ(75/50/150)/4RH(75/50) | M3: Treatment regimen: 2RHZ(75/50/150)/4RH(75/50)
B4: 12-15 kg weight band | M4: 12-15 kg weight band
B6: Intensive Phase | M6: Intensive Phase
B7: Medicine | C7: Strength | D7: Cost per tablet | E7: Daily Dose in tablet | F7: Days in Months | G7: No. of months | H7: Full treatment / Number of tablets required | I7: Cost of Intensive Phase in US$ | M7: Medicine | N7: Strength | O7: Cost per tablet | P7: Daily Dose in BUC | Q7: Days in Months | R7: No. of months | S7: Full treatment / Number of tablets required | T7: Cost of Intensive Phase in US$
B8: RHZ (75/50/150) | C8: 275 mg | D8: =3.4/84 -> 0.04047619 | E8: 3 | F8: 30 | G8: 2 | H8: =E8*F8*G8 -> 180 | I8: =D8*H8 -> 7.2857143 | M8: RHZ (75/50/150) | N8: 275 mg | O8: 0.042857143 | P8: 3 | Q8: 30 | R8: 2 | S8: =P8*Q8*R8 -> 180 | T8: =O8*S8 -> 7.7142857
H9: Total Cost (USD) of Intensive Phase | I9: =SUM(I8:I8) -> 7.2857143 | S9: Total Cost (USD) of Intensive Phase | T9: =SUM(T8:T8) -> 7.7142857
B10: Continuation Phase | M10: Continuation Phase
B11: Medicine | C11: Strength | D11: Cost per tablet | E11: Daily Dose in tablet | F11: Days in Months | G11: No. of months | H11: Full treatment / Number of tablets required | I11: Cost of Cont Phase in US$ | M11: Medicine | N11: Strength | O11: Cost per tablet | P11: Daily Dose in tablet | Q11: Days in Months | R11: No. of months | S11: Full treatment / Number of tablets required | T11: Cost of Cont Phase in US$
B12: RH(75/50) | C12: 125 mg | D12: =2.8/84 -> 0.033333333 | E12: 3 | F12: 30 | G12: 4 | H12: =E12*F12*G12 -> 360 | I12: =D12*H12 -> 12 | M12: RH(75/50) | N12: 125 mg | O12: 0.035095238 | P12: 3 | Q12: 30 | R12: 4 | S12: =P12*Q12*R12 -> 360 | T12: =O12*S12 -> 12.634286
H13: Total Cost (USD) of Continuation Phase | I13: =SUM(I12:I12) -> 12 | S13: Total Cost (USD) of Continuation Phase | T13: =SUM(T12:T12) -> 12.634286
H15: TOTAL COST PER PATIENT FOR 6 months: | I15: =I9+I13 -> 19.285714 | S15: TOTAL COST PER PATIENT FOR 6 months: | T15: =T9+T13 -> 20.348571

Sheet SusceptibleTBavPaed 16-24 AV
B2: 2018 | M2: 2019
B3: Treatment regimen: 2RHZ(75/50/150)/4RH(75/50) | M3: Treatment regimen: 2RHZ(75/50/150)/4RH(75/50)
B4: 16-24 kg weight band | M4: 16-24 kg weight band
B6: Intensive Phase | M6: Intensive Phase
B7: Medicine | C7: Strength | D7: Cost per tablet | E7: Daily Dose in tablet | F7: Days in Months | G7: No. of months | H7: Full treatment / Number of tablets required | I7: Cost of Intensive Phase in US$ | M7: Medicine | N7: Strength | O7: Cost per tablet | P7: Daily Dose in tablet | Q7: Days in Months | R7: No. of months | S7: Full treatment / Number of tabletsrequired | T7: Cost of Intensive Phase in US$
B8: RHZ (75/50/150) | C8: 275 mg | D8: =3.4/84 -> 0.04047619 | E8: 4 | F8: 30 | G8: 2 | H8: =E8*F8*G8 -> 240 | I8: =D8*H8 -> 9.7142857 | M8: RHZ (75/50/150) | N8: 275 mg | O8: 0.042857143 | P8: 4 | Q8: 30 | R8: 2 | S8: =P8*Q8*R8 -> 240 | T8: =O8*S8 -> 10.285714
H9: Total Cost (USD) of Intensive Phase | I9: =SUM(I8:I8) -> 9.7142857 | S9: Total Cost (USD) of Intensive Phase | T9: =SUM(T8:T8) -> 10.285714
B10: Continuation Phase | M10: Continuation Phase
B11: Medicine | C11: Strength | D11: Cost per tablet | E11: Daily Dose in tablet | F11: Days in Months | G11: No. of months | H11: Full treatment / Number of tablets required | I11: Cost of Cont Phase in US$ | M11: Medicine | N11: Strength | O11: Cost per tablet | P11: Daily Dose in tablet | Q11: Days in Months | R11: No. of months | S11: Full treatment / Number of tablets required | T11: Cost of Cont Phase in US$
B12: RH(75/50) | C12: 125 mg | D12: =2.8/84 -> 0.033333333 | E12: 4 | F12: 30 | G12: 4 | H12: =E12*F12*G12 -> 480 | I12: =D12*H12 -> 16 | M12: RH(75/50) | N12: 125 mg | O12: 0.035095238 | P12: 4 | Q12: 30 | R12: 4 | S12: =P12*Q12*R12 -> 480 | T12: =O12*S12 -> 16.845714
H13: Total Cost (USD) of Continuation Phase | I13: =SUM(I12:I12) -> 16 | S13: Total Cost (USD) of Continuation Phase | T13: =SUM(T12:T12) -> 16.845714
H15: TOTAL COST PER PATIENT FOR 6 months: | I15: =I9+I13 -> 25.714286 | S15: TOTAL COST PER PATIENT FOR 6 months: | T15: =T9+T13 -> 27.131429

Sheet SusceptibleTBAdult av 25-39 AV
B2: 2018 | M2: 2019
B3: Treatment regimen: 2RHZE(150/75/400/275)/4RH(150/75) | M3: Treatment regimen: 2RHZE(150/75/400/275)/4RH(150/75)
B4: 25-39 kg weight band | M4: 25-39 kg weight band
B6: Intensive Phase | M6: Intensive Phase
B7: Medicine | C7: Strength | D7: Cost per tablet | E7: Daily Dose in tablet | F7: Days in Months | G7: No. of months | H7: Full treatment / Number of tablet required | I7: Cost of Intensive Phase in US$ | M7: Medicine | N7: Strength | O7: Cost per tablet | P7: Daily Dose in tablet | Q7: Days in Months | R7: No. of months | S7: Full treatment / Number of tablets required | T7: Cost of Intensive Phase in US$
B8: RHZE(150/75/400/275) | C8: 900 mg | D8: 0.0662 | E8: 2 | F8: 30 | G8: 2 | H8: =E8*F8*G8 -> 120 | I8: =D8*H8 -> 7.944 | M8: RHZE(150/75/400/275) | N8: 900 mg | O8: 0.07674 | P8: 2 | Q8: 30 | R8: 2 | S8: =P8*Q8*R8 -> 120 | T8: =O8*S8 -> 9.2088
H9: Total Cost (USD) of Intensive Phase | I9: =SUM(I8:I8) -> 7.944 | S9: Total Cost (USD) of Intensive Phase | T9: =SUM(T8:T8) -> 9.2088
B10: Continuation Phase | M10: Continuation Phase
B11: Medicine | C11: Strength | D11: Cost per tablet | E11: Daily Dose in tablet | F11: Days in Months | G11: No. of months | H11: Full treatment / Number of tablet required | I11: Cost of Cont Phase in US$ | M11: Medicine | N11: Strength | O11: Cost per tablet | P11: Daily Dose in tablet | Q11: Days in Months | R11: No. of months | S11: Full treatment / Number of tablets required | T11: Cost of Cont Phase in US$
B12: RH(150/75) | C12: 225 mg | D12: 0.0322 | E12: 2 | F12: 30 | G12: 4 | H12: =E12*F12*G12 -> 240 | I12: =D12*H12 -> 7.728 | M12: RH(150/75) | N12: 225 mg | O12: 0.035741071 | P12: 2 | Q12: 30 | R12: 4 | S12: =P12*Q12*R12 -> 240 | T12: =O12*S12 -> 8.5778571
H13: Total Cost (USD) of Continuation Phase | I13: =SUM(I12:I12) -> 7.728 | S13: Total Cost (USD) of Continuation Phase | T13: =SUM(T12:T12) -> 8.5778571
H15: TOTAL COST PER PATIENT FOR 6 months: | I15: =I9+I13 -> 15.672 | S15: TOTAL COST PER PATIENT FOR 6 months: | T15: =T9+T13 -> 17.786657

Sheet SuscTBAdult av 25-39 Cheapest
B1: CHEAPEST PRODUCT | M1: CHEAPEST PRODUCT
B2: 2018 | M2: 2019
B3: Treatment regimen: 2RHZE(150/75/400/275)/4RH(150/75) | M3: Treatment regimen: 2RHZE(150/75/400/275)/4RH(150/75)
B4: 25-39 kg weight band | M4: 25-39 kg weight band
B6: Intensive Phase | M6: Intensive Phase
B7: Medicine | C7: Strength | D7: Cost per tablet | E7: Daily Dose in tablet | F7: Days in Months | G7: No. of months | H7: Full treatment / Number of tablet required | I7: Cost of Intensive Phase in US$ | M7: Medicine | N7: Strength | O7: Cost per tablet | P7: Daily Dose in tablet | Q7: Days in Months | R7: No. of months | S7: Full treatment / Number of tablets required | T7: Cost of Intensive Phase in US$
B8: RHZE(150/75/400/275) | C8: 900 mg | D8: 0.0596 | E8: 2 | F8: 30 | G8: 2 | H8: =E8*F8*G8 -> 120 | I8: =D8*H8 -> 7.152 | M8: RHZE(150/75/400/275) | N8: 900 mg | O8: 0.0712 | P8: 2 | Q8: 30 | R8: 2 | S8: =P8*Q8*R8 -> 120 | T8: =O8*S8 -> 8.544
H9: Total Cost (USD) of Intensive Phase | I9: =SUM(I8:I8) -> 7.152 | S9: Total Cost (USD) of Intensive Phase | T9: =SUM(T8:T8) -> 8.544
B10: Continuation Phase | M10: Continuation Phase
B11: Medicine | C11: Strength | D11: Cost per tablet | E11: Daily Dose in tablet | F11: Days in Months | G11: No. of months | H11: Full treatment / Number of tablet required | I11: Cost of Cont Phase in US$ | M11: Medicine | N11: Strength | O11: Cost per tablet | P11: Daily Dose in tablet | Q11: Days in Months | R11: No. of months | S11: Full treatment / Number of tablets required | T11: Cost of Cont Phase in US$
B12: RH(150/75) | C12: 225 mg | D12: 0.0294 | E12: 2 | F12: 30 | G12: 4 | H12: =E12*F12*G12 -> 240 | I12: =D12*H12 -> 7.056 | M12: RH(150/75) | N12: 225 mg | O12: 0.0294 | P12: 2 | Q12: 30 | R12: 4 | S12: =P12*Q12*R12 -> 240 | T12: =O12*S12 -> 7.056
H13: Total Cost (USD) of Continuation Phase | I13: =SUM(I12:I12) -> 7.056 | S13: Total Cost (USD) of Continuation Phase | T13: =SUM(T12:T12) -> 7.056
H15: TOTAL COST PER PATIENT FOR 6 months: | I15: =I9+I13 -> 14.208 | S15: TOTAL COST PER PATIENT FOR 6 months: | T15: =T9+T13 -> 15.6

Sheet SusceptibleTBAdult av 40-54 AV
B2: 2018 | M2: 2019
B3: Treatment regimen: 2RHZE(150/75/400/275)/4RH(150/75) | M3: Treatment regimen: 2RHZE(150/75/400/275)/4RH(150/75)
B4: 40-54 kg weight band | M4: 40-54 kg weight band
B6: Intensive Phase | M6: Intensive Phase
B7: Medicine | C7: Strength | D7: Cost per tablet | E7: Daily Dose in tablet | F7: Days in Months | G7: No. of months | H7: Full treatment / Number of tablets required | I7: Cost of Intensive Phase in US$ | M7: Medicine | N7: Strength | O7: Cost per tablet | P7: Daily Dose in tablet | Q7: Days in Months | R7: No. of months | S7: Full treatment / Number of tablets required | T7: Cost of Intensive Phase in US$
B8: RHZE(150/75/400/275) | C8: 900 mg | D8: 0.0662 | E8: 3 | F8: 30 | G8: 2 | H8: =E8*F8*G8 -> 180 | I8: =D8*H8 -> 11.916 | M8: RHZE(150/75/400/275) | N8: 900 mg | O8: 0.07674 | P8: 3 | Q8: 30 | R8: 2 | S8: =P8*Q8*R8 -> 180 | T8: =O8*S8 -> 13.8132
H9: Total Cost (USD) of Intensive Phase | I9: =SUM(I8:I8) -> 11.916 | S9: Total Cost (USD) of Intensive Phase | T9: =SUM(T8:T8) -> 13.8132
B10: Continuation Phase | M10: Continuation Phase
B11: Medicine | C11: Strength | D11: Cost per tablet | E11: Daily Dose in tablet | F11: Days in Months | G11: No. of months | H11: Full treatment / Number of tablets required | I11: Cost of Cont Phase in US$ | M11: Medicine | N11: Strength | O11: Cost per tablet | P11: Daily Dose in tablet | Q11: Days in Months | R11: No. of months | S11: Full treatment / Number of tablets required | T11: Cost of Cont Phase in US$
B12: RH(150/75) | C12: 225 mg | D12: 0.0322 | E12: 3 | F12: 30 | G12: 4 | H12: =E12*F12*G12 -> 360 | I12: =D12*H12 -> 11.592 | M12: RH(150/75) | N12: 225 mg | O12: 0.035741071 | P12: 3 | Q12: 30 | R12: 4 | S12: =P12*Q12*R12 -> 360 | T12: =O12*S12 -> 12.866786
H13: Total Cost (USD) of Continuation Phase | I13: =SUM(I12:I12) -> 11.592 | S13: Total Cost (USD) of Continuation Phase | T13: =SUM(T12:T12) -> 12.866786
H15: TOTAL COST PER PATIENT FOR 6 months: | I15: =I9+I13 -> 23.508 | S15: TOTAL COST PER PATIENT FOR 6 months: | T15: =T9+T13 -> 26.679986

Sheet SuscTBAdult av 40-54 Cheapest
B1: CHEAPEST PRODUCT | M1: CHEAPEST PRODUCT
B2: 2018 | M2: 2019
B3: Treatment regimen: 2RHZE(150/75/400/275)/4RH(150/75) | M3: Treatment regimen: 2RHZE(150/75/400/275)/4RH(150/75)
B4: 40-54 kg weight band | M4: 40-54 kg weight band
B6: Intensive Phase | M6: Intensive Phase
B7: Medicine | C7: Strength | D7: Cost per tablet | E7: Daily Dose in tablet | F7: Days in Months | G7: No. of months | H7: Full treatment / Number of tablets required | I7: Cost of Intensive Phase in US$ | M7: Medicine | N7: Strength | O7: Cost per tablet | P7: Daily Dose in tablet | Q7: Days in Months | R7: No. of months | S7: Full treatment / Number of tablets required | T7: Cost of Intensive Phase in US$
B8: RHZE(150/75/400/275) | C8: 900 mg | D8: 0.0596 | E8: 3 | F8: 30 | G8: 2 | H8: =E8*F8*G8 -> 180 | I8: =D8*H8 -> 10.728 | M8: RHZE(150/75/400/275) | N8: 900 mg | O8: 0.0712 | P8: 3 | Q8: 30 | R8: 2 | S8: =P8*Q8*R8 -> 180 | T8: =O8*S8 -> 12.816
H9: Total Cost (USD) of Intensive Phase | I9: =SUM(I8:I8) -> 10.728 | S9: Total Cost (USD) of Intensive Phase | T9: =SUM(T8:T8) -> 12.816
B10: Continuation Phase | M10: Continuation Phase
B11: Medicine | C11: Strength | D11: Cost per tablet | E11: Daily Dose in tablet | F11: Days in Months | G11: No. of months | H11: Full treatment / Number of tablets required | I11: Cost of Cont Phase in US$ | M11: Medicine | N11: Strength | O11: Cost per tablet | P11: Daily Dose in tablet | Q11: Days in Months | R11: No. of months | S11: Full treatment / Number of tablets required | T11: Cost of Cont Phase in US$
B12: RH(150/75) | C12: 225 mg | D12: 0.0294 | E12: 3 | F12: 30 | G12: 4 | H12: =E12*F12*G12 -> 360 | I12: =D12*H12 -> 10.584 | M12: RH(150/75) | N12: 225 mg | O12: 0.0294 | P12: 3 | Q12: 30 | R12: 4 | S12: =P12*Q12*R12 -> 360 | T12: =O12*S12 -> 10.584
H13: Total Cost (USD) of Continuation Phase | I13: =SUM(I12:I12) -> 10.584 | S13: Total Cost (USD) of Continuation Phase | T13: =SUM(T12:T12) -> 10.584
H15: TOTAL COST PER PATIENT FOR 6 months: | I15: =I9+I13 -> 21.312 | S15: TOTAL COST PER PATIENT FOR 6 months: | T15: =T9+T13 -> 23.4

Sheet SusceptibleTBAdult av 55-70 AV
B2: 2018 | M2: 2019
B3: Treatment regimen: 2RHZE(150/75/400/275)/4RH(150/75) | M3: Treatment regimen: 2RHZE(150/75/400/275)/4RH(150/75)
B4: 55-70 kg weight band | M4: 55-70 kg weight band
B6: Intensive Phase | M6: Intensive Phase
B7: Medicine | C7: Strength | D7: Cost per tablet | E7: Daily Dose in tablet | F7: Days in Months | G7: No. of months | H7: Full treatment / Number of tablets required | I7: Cost of Intensive Phase in US$ | M7: Medicine | N7: Strength | O7: Cost per tablet | P7: Daily Dose in tablet | Q7: Days in Months | R7: No. of months | S7: Full treatment / Number of tablets required | T7: Cost of Intensive Phase in US$
B8: RHZE(150/75/400/275) | C8: 900 mg | D8: 0.0662 | E8: 4 | F8: 30 | G8: 2 | H8: =E8*F8*G8 -> 240 | I8: =D8*H8 -> 15.888 | M8: RHZE(150/75/400/275) | N8: 900 mg | O8: 0.07674 | P8: 4 | Q8: 30 | R8: 2 | S8: =P8*Q8*R8 -> 240 | T8: =O8*S8 -> 18.4176
H9: Total Cost (USD) of Intensive Phase | I9: =SUM(I8:I8) -> 15.888 | S9: Total Cost (USD) of Intensive Phase | T9: =SUM(T8:T8) -> 18.4176
B10: Continuation Phase | M10: Continuation Phase
B11: Medicine | C11: Strength | D11: Cost per tablet | E11: Daily Dose in tablet | F11: Days in Months | G11: No. of months | H11: Full treatment / Number of tablets required | I11: Cost of Cont Phase in US$ | M11: Medicine | N11: Strength | O11: Cost per tablet | P11: Daily Dose in tablet | Q11: Days in Months | R11: No. of months | S11: Full treatment / Number of tablets required | T11: Cost of Cont Phase in US$
B12: RH(150/75) | C12: 225 mg | D12: 0.0322 | E12: 4 | F12: 30 | G12: 4 | H12: =E12*F12*G12 -> 480 | I12: =D12*H12 -> 15.456 | M12: RH(150/75) | N12: 225 mg | O12: 0.035741071 | P12: 4 | Q12: 30 | R12: 4 | S12: =P12*Q12*R12 -> 480 | T12: =O12*S12 -> 17.155714
H13: Total Cost (USD) of Continuation Phase | I13: =SUM(I12:I12) -> 15.456 | S13: Total Cost (USD) of Continuation Phase | T13: =SUM(T12:T12) -> 17.155714
H15: TOTAL COST PER PATIENT FOR 6 months: | I15: =I9+I13 -> 31.344 | S15: TOTAL COST PER PATIENT FOR 6 months: | T15: =T9+T13 -> 35.573314

Sheet SuscTBAdult av 55-70 Cheapest
B1: CHEAPEST PRODUCT | M1: CHEAPEST PRODUCT
B2: 2018 | M2: 2019
B3: Treatment regimen: 2RHZE(150/75/400/275)/4RH(150/75) | M3: Treatment regimen: 2RHZE(150/75/400/275)/4RH(150/75)
B4: 55-70 kg weight band | M4: 55-70 kg weight band
B6: Intensive Phase | M6: Intensive Phase
B7: Medicine | C7: Strength | D7: Cost per tablet | E7: Daily Dose in tablet | F7: Days in Months | G7: No. of months | H7: Full treatment / Number of tablets required | I7: Cost of Intensive Phase in US$ | M7: Medicine | N7: Strength | O7: Cost per tablet | P7: Daily Dose in tablet | Q7: Days in Months | R7: No. of months | S7: Full treatment / Number of tablets required | T7: Cost of Intensive Phase in US$
B8: RHZE(150/75/400/275) | C8: 900 mg | D8: 0.0596 | E8: 4 | F8: 30 | G8: 2 | H8: =E8*F8*G8 -> 240 | I8: =D8*H8 -> 14.304 | M8: RHZE(150/75/400/275) | N8: 900 mg | O8: 0.0712 | P8: 4 | Q8: 30 | R8: 2 | S8: =P8*Q8*R8 -> 240 | T8: =O8*S8 -> 17.088
H9: Total Cost (USD) of Intensive Phase | I9: =SUM(I8:I8) -> 14.304 | S9: Total Cost (USD) of Intensive Phase | T9: =SUM(T8:T8) -> 17.088
B10: Continuation Phase | M10: Continuation Phase
B11: Medicine | C11: Strength | D11: Cost per tablet | E11: Daily Dose in tablet | F11: Days in Months | G11: No. of months | H11: Full treatment / Number of tablets required | I11: Cost of Cont Phase in US$ | M11: Medicine | N11: Strength | O11: Cost per tablet | P11: Daily Dose in tablet | Q11: Days in Months | R11: No. of months | S11: Full treatment / Number of tablets required | T11: Cost of Cont Phase in US$
B12: RH(150/75) | C12: 225 mg | D12: 0.0294 | E12: 4 | F12: 30 | G12: 4 | H12: =E12*F12*G12 -> 480 | I12: =D12*H12 -> 14.112 | M12: RH(150/75) | N12: 225 mg | O12: 0.0294 | P12: 4 | Q12: 30 | R12: 4 | S12: =P12*Q12*R12 -> 480 | T12: =O12*S12 -> 14.112
H13: Total Cost (USD) of Continuation Phase | I13: =SUM(I12:I12) -> 14.112 | S13: Total Cost (USD) of Continuation Phase | T13: =SUM(T12:T12) -> 14.112
H15: TOTAL COST PER PATIENT FOR 6 months: | I15: =I9+I13 -> 28.416 | S15: TOTAL COST PER PATIENT FOR 6 months: | T15: =T9+T13 -> 31.2

Sheet SusceptibleTBAdult av > 70 AV
B2: 2018 | M2: 2019
B3: Treatment regimen: 2RHZE(150/75/400/275)/4RH(150/75) | M3: Treatment regimen: 2RHZE(150/75/400/275)/4RH(150/75)
B4: > 70 kg weight band | M4: > 70 kg weight band
B6: Intensive Phase | M6: Intensive Phase
B7: Medicine | C7: Strength | D7: Cost per tablet | E7: Daily Dose in tablet | F7: Days in Months | G7: No. of months | H7: Full treatment / Number of tablets required | I7: Cost of Intensive Phase in US$ | M7: Medicine | N7: Strength | O7: Cost per tablet | P7: Daily Dose in tablet | Q7: Days in Months | R7: No. of months | S7: Full treatment / Number of tablets required | T7: Cost of Intensive Phase in US$
B8: RHZE(150/75/400/275) | C8: 900 mg | D8: 0.0662 | E8: 5 | F8: 30 | G8: 2 | H8: =E8*F8*G8 -> 300 | I8: =D8*H8 -> 19.86 | M8: RHZE(150/75/400/275) | N8: 900 mg | O8: 0.07674 | P8: 5 | Q8: 30 | R8: 2 | S8: =P8*Q8*R8 -> 300 | T8: =O8*S8 -> 23.022
H9: Total Cost (USD) of Intensive Phase | I9: =SUM(I8:I8) -> 19.86 | S9: Total Cost (USD) of Intensive Phase | T9: =SUM(T8:T8) -> 23.022
B10: Continuation Phase | M10: Continuation Phase
B11: Medicine | C11: Strength | D11: Cost per tablet | E11: Daily Dose in tablet | F11: Days in Months | G11: No. of months | H11: Full treatment / Number of tablets required | I11: Cost of Cont Phase in US$ | M11: Medicine | N11: Strength | O11: Cost per tablet | P11: Daily Dose in tablet | Q11: Days in Months | R11: No. of months | S11: Full treatment / Number of tabletsrequired | T11: Cost of Cont Phase in US$
B12: RH(150/75) | C12: 225 mg | D12: 0.0322 | E12: 5 | F12: 30 | G12: 4 | H12: =E12*F12*G12 -> 600 | I12: =D12*H12 -> 19.32 | M12: RH(150/75) | N12: 225 mg | O12: 0.035741071 | P12: 5 | Q12: 30 | R12: 4 | S12: =P12*Q12*R12 -> 600 | T12: =O12*S12 -> 21.444643
H13: Total Cost (USD) of Continuation Phase | I13: =SUM(I12:I12) -> 19.32 | S13: Total Cost (USD) of Continuation Phase | T13: =SUM(T12:T12) -> 21.444643
H15: TOTAL COST PER PATIENT FOR 6 months: | I15: =I9+I13 -> 39.18 | S15: TOTAL COST PER PATIENT FOR 6 months: | T15: =T9+T13 -> 44.466643

Sheet SusceptibleTBAdult av>70 Cheape
B1: CHEAPEST PRODUCT | M1: CHEAPEST PRODUCT
B2: 2018 | M2: 2019
B3: Treatment regimen: 2RHZE(150/75/400/275)/4RH(150/75) | M3: Treatment regimen: 2RHZE(150/75/400/275)/4RH(150/75)
B4: > 70 kg weight band | M4: > 70 kg weight band
B6: Intensive Phase | M6: Intensive Phase
B7: Medicine | C7: Strength | D7: Cost per tablet | E7: Daily Dose in tablet | F7: Days in Months | G7: No. of months | H7: Full treatment / Number of tablets required | I7: Cost of Intensive Phase in US$ | M7: Medicine | N7: Strength | O7: Cost per tablet | P7: Daily Dose in tablet | Q7: Days in Months | R7: No. of months | S7: Full treatment / Number of tablets required | T7: Cost of Intensive Phase in US$
B8: RHZE(150/75/400/275) | C8: 900 mg | D8: 0.0596 | E8: 5 | F8: 30 | G8: 2 | H8: =E8*F8*G8 -> 300 | I8: =D8*H8 -> 17.88 | M8: RHZE(150/75/400/275) | N8: 900 mg | O8: 0.0712 | P8: 5 | Q8: 30 | R8: 2 | S8: =P8*Q8*R8 -> 300 | T8: =O8*S8 -> 21.36
H9: Total Cost (USD) of Intensive Phase | I9: =SUM(I8:I8) -> 17.88 | S9: Total Cost (USD) of Intensive Phase | T9: =SUM(T8:T8) -> 21.36
B10: Continuation Phase | M10: Continuation Phase
B11: Medicine | C11: Strength | D11: Cost per tablet | E11: Daily Dose in tablet | F11: Days in Months | G11: No. of months | H11: Full treatment / Number of tablets required | I11: Cost of Cont Phase in US$ | M11: Medicine | N11: Strength | O11: Cost per tablet | P11: Daily Dose in tablet | Q11: Days in Months | R11: No. of months | S11: Full treatment / Number of tabletsrequired | T11: Cost of Cont Phase in US$
B12: RH(150/75) | C12: 225 mg | D12: 0.0294 | E12: 5 | F12: 30 | G12: 4 | H12: =E12*F12*G12 -> 600 | I12: =D12*H12 -> 17.64 | M12: RH(150/75) | N12: 225 mg | O12: 0.0294 | P12: 5 | Q12: 30 | R12: 4 | S12: =P12*Q12*R12 -> 600 | T12: =O12*S12 -> 17.64
H13: Total Cost (USD) of Continuation Phase | I13: =SUM(I12:I12) -> 17.64 | S13: Total Cost (USD) of Continuation Phase | T13: =SUM(T12:T12) -> 17.64
H15: TOTAL COST PER PATIENT FOR 6 months: | I15: =I9+I13 -> 35.52 | S15: TOTAL COST PER PATIENT FOR 6 months: | T15: =T9+T13 -> 39

Sheet Old LTR Km Eto
B2: 2018 | M2: 2019
B3: Treatment regimen: 8 Z Km Lfx Eto Cs WFI / 12 Z Lfx Eto Cs | M3: Treatment regimen: 8 Z Km Lfx Eto Cs WFI / 12 Z Lfx Eto Cs
B4: 46-55 kg weight band | M4: 46-55 kg weight band
B6: Intensive Phase | M6: Intensive Phase
B7: Medicine | C7: Strength | D7: Cost per tablet/vial | E7: Daily Dose in tablet/vial | F7: Days in Months | G7: No. of months | H7: Full treatment / Number of tablet/vial required | I7: Cost of Intensive Phase in US$ | M7: Medicine | N7: Strength | O7: Cost per tablet/vial | P7: Daily Dose in tablet/vial | Q7: Days in Months | R7: No. of months | S7: Full treatment / Number of tablet/vial required | T7: Cost of Intensive Phase in US$
B8: Pyrazinamide | C8: 400mg | D8: 0.0208 | E8: 3 | F8: 30 | G8: 8 | H8: =E8*F8*G8 -> 720 | I8: =D8*H8 -> 14.976 | M8: Pyrazinamide | N8: 400mg | O8: 0.020920476 | P8: 3 | Q8: 30 | R8: 8 | S8: =P8*Q8*R8 -> 720 | T8: =O8*S8 -> 15.062743
B9: Kanamycin | C9: 1 g | D9: 0.92 | E9: 1 | F9: 30 | G9: 8 | H9: =E9*F9*G9 -> 240 | I9: =D9*H9 -> 220.8 | M9: Kanamycin | N9: 1 g | O9: 0.667 | P9: 1 | Q9: 30 | R9: 8 | S9: =P9*Q9*R9 -> 240 | T9: =O9*S9 -> 160.08
B10: Levofloxacin | C10: 250 mg | D10: 0.02734 | E10: 4 | F10: 30 | G10: 8 | H10: =E10*F10*G10 -> 960 | I10: =D10*H10 -> 26.2464 | M10: Levofloxacin | N10: 250 mg | O10: 0.02815 | P10: 4 | Q10: 30 | R10: 8 | S10: =P10*Q10*R10 -> 960 | T10: =O10*S10 -> 27.024
B11: Ethionamide | C11: 250 mg | D11: 0.0793 | E11: 3 | F11: 30 | G11: 8 | H11: =E11*F11*G11 -> 720 | I11: =D11*H11 -> 57.096 | M11: Ethionamide | N11: 250 mg | O11: 0.09688 | P11: 3 | Q11: 30 | R11: 8 | S11: =P11*Q11*R11 -> 720 | T11: =O11*S11 -> 69.7536
B12: Cycloserine | C12: 250 mg | D12: 0.2594 | E12: 2 | F12: 30 | G12: 8 | H12: =E12*F12*G12 -> 480 | I12: =D12*H12 -> 124.512 | M12: Cycloserine | N12: 250 mg | O12: 0.2519 | P12: 2 | Q12: 30 | R12: 8 | S12: =P12*Q12*R12 -> 480 | T12: =O12*S12 -> 120.912
H13: Total Cost (USD) of Intensive Phase | I13: =SUM(I8:I12) -> 443.6304 | S13: Total Cost (USD) of Intensive Phase | T13: =SUM(T8:T12) -> 392.83234
B14: Continuation Phase | M14: Continuation Phase
B15: Medicine | C15: Strength | D15: Cost per tablet/vial | E15: Daily Dose in tablet/vial | F15: Days in Months | G15: No. of months | H15: Full treatment / Number of tablet/vial required | I15: Cost of Cont Phase in US$ | M15: Medicine | N15: Strength | O15: Cost per tablet/vial | P15: Daily Dose in tablet/vial | Q15: Days in Months | R15: No. of months | S15: Full treatment / Number of tablet/vial required | T15: Cost of Cont Phase in US$
B16: Pyrazinamide | C16: 400mg | D16: =D8 -> 0.0208 | E16: 3 | F16: 30 | G16: 12 | H16: =E16*F16*G16 -> 1080 | I16: =D16*H16 -> 22.464 | M16: Pyrazinamide | N16: 400mg | O16: =O8 -> 0.020920476 | P16: 3 | Q16: 30 | R16: 12 | S16: =P16*Q16*R16 -> 1080 | T16: =O16*S16 -> 22.594114
B17: Levofloxacin | C17: 250 mg | D17: =D10 -> 0.02734 | E17: 4 | F17: 30 | G17: 12 | H17: =E17*F17*G17 -> 1440 | I17: =D17*H17 -> 39.3696 | M17: Levofloxacin | N17: 250 mg | O17: =O10 -> 0.02815 | P17: 4 | Q17: 30 | R17: 12 | S17: =P17*Q17*R17 -> 1440 | T17: =O17*S17 -> 40.536
B18: Ethionamide | C18: 250 mg | D18: =D11 -> 0.0793 | E18: 3 | F18: 30 | G18: 12 | H18: =E18*F18*G18 -> 1080 | I18: =D18*H18 -> 85.644 | M18: Ethionamide | N18: 250 mg | O18: =O11 -> 0.09688 | P18: 3 | Q18: 30 | R18: 12 | S18: =P18*Q18*R18 -> 1080 | T18: =O18*S18 -> 104.6304
B19: Cycloserine | C19: 250 mg | D19: =D12 -> 0.2594 | E19: 2 | F19: 30 | G19: 12 | H19: =E19*F19*G19 -> 720 | I19: =D19*H19 -> 186.768 | M19: Cycloserine | N19: 250 mg | O19: =O12 -> 0.2519 | P19: 2 | Q19: 30 | R19: 12 | S19: =P19*Q19*R19 -> 720 | T19: =O19*S19 -> 181.368
H20: Total Cost (USD) of Continuation Phase | I20: =SUM(I16:I19) -> 334.2456 | S20: Total Cost (USD) of Continuation Phase | T20: =SUM(T16:T19) -> 349.12851
H22: TOTAL COST PER PATIENT FOR 20 months: | I22: =I13+I20 -> 777.876 | S22: TOTAL COST PER PATIENT FOR 20 months: | T22: =T13+T20 -> 741.96086

Sheet Old LTR Km Eto cheapest
B2: 2018 | M2: 2019
B3: Treatment regimen: 8 Z Km Lfx Eto Cs WFI / 12 Z Lfx Eto Cs | M3: Treatment regimen: 8 Z Km Lfx Eto Cs WFI / 12 Z Lfx Eto Cs
B4: 46-55 kg weight band | M4: 46-55 kg weight band
B5: CHEAPEST | M5: CHEAPEST
B6: Intensive Phase | M6: Intensive Phase
B7: Medicine | C7: Strength | D7: Cost per tablet/vial | E7: Daily Dose in tablet/vial | F7: Days in Months | G7: No. of months | H7: Full treatment / Number of tablet/vial required | I7: Cost of Intensive Phase in US$ | M7: Medicine | N7: Strength | O7: Cost per tablet/vial | P7: Daily Dose in tablet/vial | Q7: Days in Months | R7: No. of months | S7: Full treatment / Number of tablet/vial required | T7: Cost of Intensive Phase in US$
B8: Pyrazinamide | C8: 400mg | D8: 0.0208 | E8: 3 | F8: 30 | G8: 8 | H8: =E8*F8*G8 -> 720 | I8: =D8*H8 -> 14.976 | M8: Pyrazinamide | N8: 400mg | O8: 0.0208 | P8: 3 | Q8: 30 | R8: 8 | S8: =P8*Q8*R8 -> 720 | T8: =O8*S8 -> 14.976
B9: Kanamycin | C9: 1 g | D9: 0.92 | E9: 1 | F9: 30 | G9: 8 | H9: =E9*F9*G9 -> 240 | I9: =D9*H9 -> 220.8 | M9: Kanamycin | N9: 1 g | O9: 0.667 | P9: 1 | Q9: 30 | R9: 8 | S9: =P9*Q9*R9 -> 240 | T9: =O9*S9 -> 160.08
B10: Levofloxacin | C10: 250 mg | D10: 0.0271 | E10: 4 | F10: 30 | G10: 8 | H10: =E10*F10*G10 -> 960 | I10: =D10*H10 -> 26.016 | M10: Levofloxacin | N10: 250 mg | O10: 0.0265 | P10: 4 | Q10: 30 | R10: 8 | S10: =P10*Q10*R10 -> 960 | T10: =O10*S10 -> 25.44
B11: Ethionamide | C11: 250 mg | D11: 0.0793 | E11: 3 | F11: 30 | G11: 8 | H11: =E11*F11*G11 -> 720 | I11: =D11*H11 -> 57.096 | M11: Ethionamide | N11: 250 mg | O11: 0.0892 | P11: 3 | Q11: 30 | R11: 8 | S11: =P11*Q11*R11 -> 720 | T11: =O11*S11 -> 64.224
B12: Cycloserine | C12: 250 mg | D12: 0.225 | E12: 2 | F12: 30 | G12: 8 | H12: =E12*F12*G12 -> 480 | I12: =D12*H12 -> 108 | M12: Cycloserine | N12: 250 mg | O12: 0.24 | P12: 2 | Q12: 30 | R12: 8 | S12: =P12*Q12*R12 -> 480 | T12: =O12*S12 -> 115.2
H13: Total Cost (USD) of Intensive Phase | I13: =SUM(I8:I12) -> 426.888 | S13: Total Cost (USD) of Intensive Phase | T13: =SUM(T8:T12) -> 379.92
B14: Continuation Phase | M14: Continuation Phase
B15: Medicine | C15: Strength | D15: Cost per tablet/vial | E15: Daily Dose in tablet/vial | F15: Days in Months | G15: No. of months | H15: Full treatment / Number of tablet/vial required | I15: Cost of Cont Phase in US$ | M15: Medicine | N15: Strength | O15: Cost per tablet/vial | P15: Daily Dose in tablet/vial | Q15: Days in Months | R15: No. of months | S15: Full treatment / Number of tablet/vial required | T15: Cost of Cont Phase in US$
B16: Pyrazinamide | C16: 400mg | D16: =D8 -> 0.0208 | E16: 3 | F16: 30 | G16: 12 | H16: =E16*F16*G16 -> 1080 | I16: =D16*H16 -> 22.464 | M16: Pyrazinamide | N16: 400mg | O16: =O8 -> 0.0208 | P16: 3 | Q16: 30 | R16: 12 | S16: =P16*Q16*R16 -> 1080 | T16: =O16*S16 -> 22.464
B17: Levofloxacin | C17: 250 mg | D17: =D10 -> 0.0271 | E17: 4 | F17: 30 | G17: 12 | H17: =E17*F17*G17 -> 1440 | I17: =D17*H17 -> 39.024 | M17: Levofloxacin | N17: 250 mg | O17: =O10 -> 0.0265 | P17: 4 | Q17: 30 | R17: 12 | S17: =P17*Q17*R17 -> 1440 | T17: =O17*S17 -> 38.16
B18: Ethionamide | C18: 250 mg | D18: =D11 -> 0.0793 | E18: 3 | F18: 30 | G18: 12 | H18: =E18*F18*G18 -> 1080 | I18: =D18*H18 -> 85.644 | M18: Ethionamide | N18: 250 mg | O18: =O11 -> 0.0892 | P18: 3 | Q18: 30 | R18: 12 | S18: =P18*Q18*R18 -> 1080 | T18: =O18*S18 -> 96.336
B19: Cycloserine | C19: 250 mg | D19: =D12 -> 0.225 | E19: 2 | F19: 30 | G19: 12 | H19: =E19*F19*G19 -> 720 | I19: =D19*H19 -> 162 | M19: Cycloserine | N19: 250 mg | O19: =O12 -> 0.24 | P19: 2 | Q19: 30 | R19: 12 | S19: =P19*Q19*R19 -> 720 | T19: =O19*S19 -> 172.8
H20: Total Cost (USD) of Continuation Phase | I20: =SUM(I16:I19) -> 309.132 | S20: Total Cost (USD) of Continuation Phase | T20: =SUM(T16:T19) -> 329.76
H22: TOTAL COST PER PATIENT FOR 20 months: | I22: =I13+I20 -> 736.02 | S22: TOTAL COST PER PATIENT FOR 20 months: | T22: =T13+T20 -> 709.68

Sheet Old LTR Mfx Km Eto
B2: 2018 | M2: 2019
B3: Treatment regimen: 8 Z KmMfx Eto Cs WFI / 12 Z Mfx Eto Cs | M3: Treatment regimen: 8 Z Km Mfx Eto Cs WFI / 12 Z Mfx Eto Cs
B4: 46-55 kg weight band | M4: 46-55 kg weight band
B6: Intensive Phase | M6: Intensive Phase
B7: Medicine | C7: Strength | D7: Cost per tablet/vial | E7: Daily Dose in tablet/vial | F7: Days in Months | G7: No. of months | H7: Full treatment / Number of tablet/vial required | I7: Cost of Intensive Phase in US$ | M7: Medicine | N7: Strength | O7: Cost per tablet/vial | P7: Daily Dose in tablet/vial | Q7: Days in Months | R7: No. of months | S7: Full treatment / Number of tablet/vial required | T7: Cost of Intensive Phase in US$
B8: Pyrazinamide | C8: 400mg | D8: 0.0208 | E8: 3 | F8: 30 | G8: 8 | H8: =E8*F8*G8 -> 720 | I8: =D8*H8 -> 14.976 | M8: Pyrazinamide | N8: 400mg | O8: 0.020920476 | P8: 3 | Q8: 30 | R8: 8 | S8: =P8*Q8*R8 -> 720 | T8: =O8*S8 -> 15.062743
B9: Kanamycin | C9: 1 g | D9: 0.92 | E9: 1 | F9: 30 | G9: 8 | H9: =E9*F9*G9 -> 240 | I9: =D9*H9 -> 220.8 | M9: Kanamycin | N9: 1 g | O9: 0.667 | P9: 1 | Q9: 30 | R9: 8 | S9: =P9*Q9*R9 -> 240 | T9: =O9*S9 -> 160.08
B10: Moxifloxacin | C10: 250 mg | D10: 0.2643 | E10: 2 | F10: 30 | G10: 8 | H10: =E10*F10*G10 -> 480 | I10: =D10*H10 -> 126.864 | M10: Moxifloxacin | N10: 400 mg | O10: 0.219535 | P10: 2 | Q10: 30 | R10: 8 | S10: =P10*Q10*R10 -> 480 | T10: =O10*S10 -> 105.3768
B11: Ethionamide | C11: 250 mg | D11: 0.0793 | E11: 3 | F11: 30 | G11: 8 | H11: =E11*F11*G11 -> 720 | I11: =D11*H11 -> 57.096 | M11: Ethionamide | N11: 250 mg | O11: 0.09688 | P11: 3 | Q11: 30 | R11: 8 | S11: =P11*Q11*R11 -> 720 | T11: =O11*S11 -> 69.7536
B12: Cycloserine | C12: 250 mg | D12: 0.2594 | E12: 2 | F12: 30 | G12: 8 | H12: =E12*F12*G12 -> 480 | I12: =D12*H12 -> 124.512 | M12: Cycloserine | N12: 250 mg | O12: 0.2519 | P12: 2 | Q12: 30 | R12: 8 | S12: =P12*Q12*R12 -> 480 | T12: =O12*S12 -> 120.912
H13: Total Cost (USD) of Intensive Phase | I13: =SUM(I8:I12) -> 544.248 | S13: Total Cost (USD) of Intensive Phase | T13: =SUM(T8:T12) -> 471.18514
B14: Continuation Phase | M14: Continuation Phase
B15: Medicine | C15: Strength | D15: Cost per tablet/vial | E15: Daily Dose in tablet/vial | F15: Days in Months | G15: No. of months | H15: Full treatment / Number of tablet/vial required | I15: Cost of Cont Phase in US$ | M15: Medicine | N15: Strength | O15: Cost per tablet/vial | P15: Daily Dose in tablet/vial | Q15: Days in Months | R15: No. of months | S15: Full treatment / Number of tablet/vial required | T15: Cost of Cont Phase in US$
B16: Pyrazinamide | C16: 400mg | D16: =D8 -> 0.0208 | E16: 3 | F16: 30 | G16: 12 | H16: =E16*F16*G16 -> 1080 | I16: =D16*H16 -> 22.464 | M16: Pyrazinamide | N16: 400mg | O16: =O8 -> 0.020920476 | P16: 3 | Q16: 30 | R16: 12 | S16: =P16*Q16*R16 -> 1080 | T16: =O16*S16 -> 22.594114
B17: Moxifloxacin | C17: 250 mg | D17: =D10 -> 0.2643 | E17: 2 | F17: 30 | G17: 12 | H17: =E17*F17*G17 -> 720 | I17: =D17*H17 -> 190.296 | M17: Moxifloxacin | N17: 400 mg | O17: =O10 -> 0.219535 | P17: 2 | Q17: 30 | R17: 12 | S17: =P17*Q17*R17 -> 720 | T17: =O17*S17 -> 158.0652
B18: Ethionamide | C18: 250 mg | D18: =D11 -> 0.0793 | E18: 3 | F18: 30 | G18: 12 | H18: =E18*F18*G18 -> 1080 | I18: =D18*H18 -> 85.644 | M18: Ethionamide | N18: 250 mg | O18: =O11 -> 0.09688 | P18: 3 | Q18: 30 | R18: 12 | S18: =P18*Q18*R18 -> 1080 | T18: =O18*S18 -> 104.6304
B19: Cycloserine | C19: 250 mg | D19: =D12 -> 0.2594 | E19: 2 | F19: 30 | G19: 12 | H19: =E19*F19*G19 -> 720 | I19: =D19*H19 -> 186.768 | M19: Cycloserine | N19: 250 mg | O19: =O12 -> 0.2519 | P19: 2 | Q19: 30 | R19: 12 | S19: =P19*Q19*R19 -> 720 | T19: =O19*S19 -> 181.368
H20: Total Cost (USD) of Continuation Phase | I20: =SUM(I16:I19) -> 485.172 | S20: Total Cost (USD) of Continuation Phase | T20: =SUM(T16:T19) -> 466.65771
H22: TOTAL COST PER PATIENT FOR 20 months: | I22: =I13+I20 -> 1029.42 | S22: TOTAL COST PER PATIENT FOR 20 months: | T22: =T13+T20 -> 937.84286

Sheet Old LTR Km Pto
B2: 2018 | M2: 2019
B3: Treatment regimen: 8 Z Km Lfx Pto Cs WFI / 12 Z Lfx Pto Cs | M3: Treatment regimen: 8 Z Km Lfx Pto Cs WFI / 12 Z Lfx Pto Cs
B4: 46-55 kg weight band | M4: 46-55 kg weight band
B6: Intensive Phase | M6: Intensive Phase
B7: Medicine | C7: Strength | D7: Cost per tablet/vial | E7: Daily Dose in tablet/vial | F7: Days in Months | G7: No. of months | H7: Full treatment / Number of tablet/vial required | I7: Cost of Intensive Phase in US$ | M7: Medicine | N7: Strength | O7: Cost per tablet/vial | P7: Daily Dose in tablet/vial | Q7: Days in Months | R7: No. of months | S7: Full treatment / Number of tablet/vial required | T7: Cost of Intensive Phase in US$
B8: Pyrazinamide | C8: 400mg | D8: ='Old LTR Km Eto'!D8 -> 0.0208 | E8: 3 | F8: 30 | G8: 8 | H8: =E8*F8*G8 -> 720 | I8: =D8*H8 -> 14.976 | M8: Pyrazinamide | N8: 400mg | O8: 0.020920476 | P8: 3 | Q8: 30 | R8: 8 | S8: =P8*Q8*R8 -> 720 | T8: =O8*S8 -> 15.062743
B9: Kanamycin | C9: 1 g | D9: ='Old LTR Km Eto'!D9 -> 0.92 | E9: 1 | F9: 30 | G9: 8 | H9: =E9*F9*G9 -> 240 | I9: =D9*H9 -> 220.8 | M9: Kanamycin | N9: 1 g | O9: 0.667 | P9: 1 | Q9: 30 | R9: 8 | S9: =P9*Q9*R9 -> 240 | T9: =O9*S9 -> 160.08
B10: Levofloxacin | C10: 250 mg | D10: ='Old LTR Km Eto'!D10 -> 0.02734 | E10: 4 | F10: 30 | G10: 8 | H10: =E10*F10*G10 -> 960 | I10: =D10*H10 -> 26.2464 | M10: Levofloxacin | N10: 250 mg | O10: 0.02815 | P10: 4 | Q10: 30 | R10: 8 | S10: =P10*Q10*R10 -> 960 | T10: =O10*S10 -> 27.024
B11: Prothionamide | C11: 250 mg | D11: 0.086245 | E11: 3 | F11: 30 | G11: 8 | H11: =E11*F11*G11 -> 720 | I11: =D11*H11 -> 62.0964 | M11: Prothionamide | N11: 250 mg | O11: 0.10357 | P11: 3 | Q11: 30 | R11: 8 | S11: =P11*Q11*R11 -> 720 | T11: =O11*S11 -> 74.5704
B12: Cycloserine | C12: 250 mg | D12: ='Old LTR Km Eto'!D12 -> 0.2594 | E12: 2 | F12: 30 | G12: 8 | H12: =E12*F12*G12 -> 480 | I12: =D12*H12 -> 124.512 | M12: Cycloserine | N12: 250 mg | O12: 0.2519 | P12: 2 | Q12: 30 | R12: 8 | S12: =P12*Q12*R12 -> 480 | T12: =O12*S12 -> 120.912
H13: Total Cost (USD) of Intensive Phase | I13: =SUM(I8:I12) -> 448.6308 | S13: Total Cost (USD) of Intensive Phase | T13: =SUM(T8:T12) -> 397.64914
B14: Continuation Phase | M14: Continuation Phase
B15: Medicine | C15: Strength | D15: Cost per tablet/vial | E15: Daily Dose in tablet/vial | F15: Days in Months | G15: No. of months | H15: Full treatment / Number of tablet/vial required | I15: ='Old LTR Km Eto'!I15 -> Cost of Cont Phase in US$ | M15: Medicine | N15: Strength | O15: Cost per tablet/vial | P15: Daily Dose in tablet/vial | Q15: Days in Months | R15: No. of months | S15: Full treatment / Number of tablet/vial required | T15: ='Old LTR Km Eto'!T15 -> Cost of Cont Phase in US$
B16: Pyrazinamide | C16: 400mg | D16: =D8 -> 0.0208 | E16: 3 | F16: 30 | G16: 12 | H16: =E16*F16*G16 -> 1080 | I16: =D16*H16 -> 22.464 | M16: Pyrazinamide | N16: 400mg | O16: =O8 -> 0.020920476 | P16: 3 | Q16: 30 | R16: 12 | S16: =P16*Q16*R16 -> 1080 | T16: =O16*S16 -> 22.594114
B17: Levofloxacin | C17: 250 mg | D17: =D10 -> 0.02734 | E17: 4 | F17: 30 | G17: 12 | H17: =E17*F17*G17 -> 1440 | I17: =D17*H17 -> 39.3696 | M17: Levofloxacin | N17: 250 mg | O17: =O10 -> 0.02815 | P17: 4 | Q17: 30 | R17: 12 | S17: =P17*Q17*R17 -> 1440 | T17: =O17*S17 -> 40.536
B18: Prothionamide | C18: 250 mg | D18: =D11 -> 0.086245 | E18: 3 | F18: 30 | G18: 12 | H18: =E18*F18*G18 -> 1080 | I18: =D18*H18 -> 93.1446 | M18: Prothionamide | N18: 250 mg | O18: =O11 -> 0.10357 | P18: 3 | Q18: 30 | R18: 12 | S18: =P18*Q18*R18 -> 1080 | T18: =O18*S18 -> 111.8556
B19: Cycloserine | C19: 250 mg | D19: =D12 -> 0.2594 | E19: 2 | F19: 30 | G19: 12 | H19: =E19*F19*G19 -> 720 | I19: =D19*H19 -> 186.768 | M19: Cycloserine | N19: 250 mg | O19: =O12 -> 0.2519 | P19: 2 | Q19: 30 | R19: 12 | S19: =P19*Q19*R19 -> 720 | T19: =O19*S19 -> 181.368
H20: Total Cost (USD) of Continuation Phase | I20: =SUM(I16:I19) -> 341.7462 | S20: Total Cost (USD) of Continuation Phase | T20: =SUM(T16:T19) -> 356.35371
H22: TOTAL COST PER PATIENT FOR 24 months: | I22: =I13+I20 -> 790.377 | S22: TOTAL COST PER PATIENT FOR 24 months: | T22: =T13+T20 -> 754.00286

Sheet Old LTR Mfx Cm Eto
B2: 2018 | M2: 2019
B3: Treatment regimen: 8 Z Cm Mfx Eto Cs WFI / 12 Z Mfx Eto Cs | M3: Treatment regimen: 8 Z Cm mfx Eto Cs WFI / 12 Z mfx Eto Cs
B4: 46-55 kg weight band | M4: 46-55 kg weight band
B6: Intensive Phase | M6: Intensive Phase
B7: Medicine | C7: Strength | D7: Cost per tablet/vial/amp | E7: Daily Dose in Tablet/vial/amp | F7: Days in Months | G7: No. of months | H7: Full treatment / Number of tablet/vial required | I7: Cost of Intensive Phase in US$ | M7: Medicine | N7: Strength | O7: Cost per tablet/vial | P7: Daily Dose in tablet/vial | Q7: Days in Months | R7: No. of months | S7: Full treatment / Number of tablet/vial required | T7: Cost of Intensive Phase in US$
B8: Pyrazinamide | C8: 400mg | D8: 0.0208 | E8: 3 | F8: 30 | G8: 8 | H8: =E8*F8*G8 -> 720 | I8: =D8*H8 -> 14.976 | M8: Pyrazinamide | N8: 400mg | O8: 0.020920476 | P8: 3 | Q8: 30 | R8: 8 | S8: =P8*Q8*R8 -> 720 | T8: =O8*S8 -> 15.062743
B9: Capreomycin | C9: 1 g | D9: 3.3169 | E9: 1 | F9: 30 | G9: 8 | H9: =E9*F9*G9 -> 240 | I9: =D9*H9 -> 796.056 | M9: Capreomycin | N9: 1 g | O9: 2.239 | P9: 1 | Q9: 30 | R9: 8 | S9: =P9*Q9*R9 -> 240 | T9: =O9*S9 -> 537.36
B10: Moxifloxacin | C10: 400 mg | D10: 0.2643 | E10: 2 | F10: 30 | G10: 8 | H10: =E10*F10*G10 -> 480 | I10: =D10*H10 -> 126.864 | M10: Moxifloxacin | N10: 400 mg | O10: 0.219535 | P10: 2 | Q10: 30 | R10: 8 | S10: =P10*Q10*R10 -> 480 | T10: =O10*S10 -> 105.3768
B11: Ethionamide | C11: 250 mg | D11: 0.0793 | E11: 3 | F11: 30 | G11: 8 | H11: =E11*F11*G11 -> 720 | I11: =D11*H11 -> 57.096 | M11: Ethionamide | N11: 250 mg | O11: 0.09688 | P11: 3 | Q11: 30 | R11: 8 | S11: =P11*Q11*R11 -> 720 | T11: =O11*S11 -> 69.7536
B12: Cycloserine | C12: 250 mg | D12: 0.2594 | E12: 2 | F12: 30 | G12: 8 | H12: =E12*F12*G12 -> 480 | I12: =D12*H12 -> 124.512 | M12: Cycloserine | N12: 250 mg | O12: 0.2519 | P12: 2 | Q12: 30 | R12: 8 | S12: =P12*Q12*R12 -> 480 | T12: =O12*S12 -> 120.912
H13: Total Cost (USD) of Intensive Phase | I13: =SUM(I8:I12) -> 1119.504 | S13: Total Cost (USD) of Intensive Phase | T13: =SUM(T8:T12) -> 848.46514
B14: Continuation Phase | M14: Continuation Phase
B15: Medicine | C15: Strength | D15: Cost per tablet/vial/amp | E15: Daily Dose in Tablet/vial/amp | F15: Days in Months | G15: No. of months | H15: Full treatment / Number of tablet/vial required | I15: Cost of Cont Phase in US$ | M15: Medicine | N15: Strength | O15: Cost per tablet/vial | P15: Daily Dose in tablet/vial | Q15: Days in Months | R15: No. of months | S15: Full treatment / Number of tablet/vial required | T15: Cost of Cont Phase in US$
B16: Pyrazinamide | C16: 400mg | D16: =D8 -> 0.0208 | E16: 3 | F16: 30 | G16: 12 | H16: =E16*F16*G16 -> 1080 | I16: =D16*H16 -> 22.464 | M16: Pyrazinamide | N16: 400mg | O16: =O8 -> 0.020920476 | P16: 3 | Q16: 30 | R16: 12 | S16: =P16*Q16*R16 -> 1080 | T16: =O16*S16 -> 22.594114
B17: Moxifloxacin | C17: 250 mg | D17: =D10 -> 0.2643 | E17: 2 | F17: 30 | G17: 12 | H17: =E17*F17*G17 -> 720 | I17: =D17*H17 -> 190.296 | M17: Moxifloxacin | N17: 400 mg | O17: =O10 -> 0.219535 | P17: 2 | Q17: 30 | R17: 12 | S17: =P17*Q17*R17 -> 720 | T17: =O17*S17 -> 158.0652
B18: Ethionamide | C18: 250 mg | D18: =D11 -> 0.0793 | E18: 3 | F18: 30 | G18: 12 | H18: =E18*F18*G18 -> 1080 | I18: =D18*H18 -> 85.644 | M18: Ethionamide | N18: 250 mg | O18: =O11 -> 0.09688 | P18: 3 | Q18: 30 | R18: 12 | S18: =P18*Q18*R18 -> 1080 | T18: =O18*S18 -> 104.6304
B19: Cycloserine | C19: 250 mg | D19: =D12 -> 0.2594 | E19: 2 | F19: 30 | G19: 12 | H19: =E19*F19*G19 -> 720 | I19: =D19*H19 -> 186.768 | M19: Cycloserine | N19: 250 mg | O19: =O12 -> 0.2519 | P19: 2 | Q19: 30 | R19: 12 | S19: =P19*Q19*R19 -> 720 | T19: =O19*S19 -> 181.368
H20: Total Cost (USD) of Continuation Phase | I20: =SUM(I16:I19) -> 485.172 | S20: Total Cost (USD) of Continuation Phase | T20: =SUM(T16:T19) -> 466.65771
H22: TOTAL COST PER PATIENT FOR 20 months: | I22: =I13+I20 -> 1604.676 | S22: TOTAL COST PER PATIENT FOR 20 months: | T22: =T13+T20 -> 1315.1229
B24: Updated Example of low end-of-range cost calculation for one country
B25: Treatment regimen 8 Am Eto Cs Lfx/ 16 Eto Cs Lfx
B26: December 2011 EXW manufacturers prices
B28: Intensive Phase
B29: Medicine | C29: Strength | D29: Cost per Basic Units of Consumption (BUC) | E29: Daily Dose in BUC | F29: Days in Months | G29: No. of months | H29: Full treatment in BUC / Number of BUC required | I29: Cost of Intensive Phase in US$
B30: Amikacin | C30: 500 mg | D30: =#REF! -> #REF! | E30: 2 | F30: 30 | G30: 8 | H30: =E30*F30*G30 -> 480 | I30: =D30*H30 -> #REF!
B31: Ethionamide | C31: 250 mg | D31: =#REF! -> #REF! | E31: 3 | F31: 30 | G31: 8 | H31: =E31*F31*G31 -> 720 | I31: =D31*H31 -> #REF!
B32: Cycloserin | C32: 250 mg | D32: =#REF! -> #REF! | E32: 3 | F32: 30 | G32: 8 | H32: =E32*F32*G32 -> 720 | I32: =D32*H32 -> #REF!
B33: Levofloxacin | C33: 250 mg | D33: =#REF! -> #REF! | E33: 3 | F33: 30 | G33: 8 | H33: =E33*F33*G33 -> 720 | I33: =D33*H33 -> #REF!
H34: Total Cost (USD) of Intensive Phase | I34: =SUM(I30:I33) -> #REF!
B35: Continuation Phase
B36: Medicine | C36: Strength | D36: Cost per Basic Units of Consumption (BUC) | E36: Daily Dose in BUC | F36: Days in Months | G36: No. of months | H36: Full treatment in BUC / Number of BUC required | I36: Cost of Intensive Phase in US$
B37: Ethionamide | C37: 250 mg | D37: =#REF! -> #REF! | E37: 3 | F37: 30 | G37: 16 | H37: =E37*F37*G37 -> 1440 | I37: =D37*H37 -> #REF!
B38: Cycloserin | C38: 250 mg | D38: =#REF! -> #REF! | E38: 3 | F38: 30 | G38: 16 | H38: =E38*F38*G38 -> 1440 | I38: =D38*H38 -> #REF!
B39: Levoxloxacin | C39: 250 mg | D39: =#REF! -> #REF! | E39: 3 | F39: 30 | G39: 16 | H39: =E39*F39*G39 -> 1440 | I39: =D39*H39 -> #REF!
H40: Total Cost (USD) of Intensive Phase | I40: =SUM(I37:I39) -> #REF!
H42: TOTAL COST PER PATIENT FOR 24 months: | I42: =I34+I40 -> #REF!
B44: Notes: - The Cost containtment examples of low and high range have been updated according to the current treatment regimens used by the programs. The length of the intensive and continuation phase have been modified and for the high range, Moxifloxacin has been chosen as floroquinalone and for the low range Amikacin has been seclected as injectable. - The treatment cost only include the cost EXW of the drugs, it does not include related costs such as procurement fee, quality control, consolidation, etc. It is estimated that those cost will represent 10% of the cost EXW of the drugs

Sheet Old LTR Cm Eto
B2: 2018 | M2: 2019
B3: Treatment regimen: 8 Z Cm Lfx Eto Cs WFI / 12 Z Lfx Eto Cs | M3: Treatment regimen: 8 Z Cm Lfx Eto Cs WFI / 12 Z Lfx Eto Cs
B4: 46-55 kg weight band | M4: 46-55 kg weight band
B6: Intensive Phase | M6: Intensive Phase
B7: Medicine | C7: Strength | D7: Cost per tablet/vial/amp | E7: Daily Dose in Tablet/vial/amp | F7: Days in Months | G7: No. of months | H7: Full treatment / Number of tablet/vial required | I7: Cost of Intensive Phase in US$ | M7: Medicine | N7: Strength | O7: Cost per tablet/vial | P7: Daily Dose in tablet/vial | Q7: Days in Months | R7: No. of months | S7: Full treatment / Number of tablet/vial required | T7: Cost of Intensive Phase in US$
B8: Pyrazinamide | C8: 400mg | D8: 0.0208 | E8: 3 | F8: 30 | G8: 8 | H8: =E8*F8*G8 -> 720 | I8: =D8*H8 -> 14.976 | M8: Pyrazinamide | N8: 400mg | O8: 0.020920476 | P8: 3 | Q8: 30 | R8: 8 | S8: =P8*Q8*R8 -> 720 | T8: =O8*S8 -> 15.062743
B9: Capreomycin | C9: 1 g | D9: 3.3169 | E9: 1 | F9: 30 | G9: 8 | H9: =E9*F9*G9 -> 240 | I9: =D9*H9 -> 796.056 | M9: Capreomycin | N9: 1 g | O9: 2.239 | P9: 1 | Q9: 30 | R9: 8 | S9: =P9*Q9*R9 -> 240 | T9: =O9*S9 -> 537.36
B10: Levofloxacin | C10: 250 mg | D10: 0.02734 | E10: 4 | F10: 30 | G10: 8 | H10: =E10*F10*G10 -> 960 | I10: =D10*H10 -> 26.2464 | M10: Levofloxacin | N10: 250 mg | O10: 0.02815 | P10: 4 | Q10: 30 | R10: 8 | S10: =P10*Q10*R10 -> 960 | T10: =O10*S10 -> 27.024
B11: Ethionamide | C11: 250 mg | D11: 0.0793 | E11: 3 | F11: 30 | G11: 8 | H11: =E11*F11*G11 -> 720 | I11: =D11*H11 -> 57.096 | M11: Ethionamide | N11: 250 mg | O11: 0.09688 | P11: 3 | Q11: 30 | R11: 8 | S11: =P11*Q11*R11 -> 720 | T11: =O11*S11 -> 69.7536
B12: Cycloserine | C12: 250 mg | D12: 0.2594 | E12: 2 | F12: 30 | G12: 8 | H12: =E12*F12*G12 -> 480 | I12: =D12*H12 -> 124.512 | M12: Cycloserine | N12: 250 mg | O12: 0.2519 | P12: 2 | Q12: 30 | R12: 8 | S12: =P12*Q12*R12 -> 480 | T12: =O12*S12 -> 120.912
H13: Total Cost (USD) of Intensive Phase | I13: =SUM(I8:I12) -> 1018.8864 | S13: Total Cost (USD) of Intensive Phase | T13: =SUM(T8:T12) -> 770.11234
B14: Continuation Phase | M14: Continuation Phase
B15: Medicine | C15: Strength | D15: Cost per tablet/vial/amp | E15: Daily Dose in Tablet/vial/amp | F15: Days in Months | G15: No. of months | H15: Full treatment / Number of tablet/vial required | I15: Cost of Cont Phase in US$ | M15: Medicine | N15: Strength | O15: Cost per tablet/vial | P15: Daily Dose in tablet/vial | Q15: Days in Months | R15: No. of months | S15: Full treatment / Number of tablet/vial required | T15: Cost of Cont Phase in US$
B16: Pyrazinamide | C16: 400mg | D16: =D8 -> 0.0208 | E16: 3 | F16: 30 | G16: 12 | H16: =E16*F16*G16 -> 1080 | I16: =D16*H16 -> 22.464 | M16: Pyrazinamide | N16: 400mg | O16: =O8 -> 0.020920476 | P16: 3 | Q16: 30 | R16: 12 | S16: =P16*Q16*R16 -> 1080 | T16: =O16*S16 -> 22.594114
B17: Levofloxacin | C17: 250 mg | D17: =D10 -> 0.02734 | E17: 4 | F17: 30 | G17: 12 | H17: =E17*F17*G17 -> 1440 | I17: =D17*H17 -> 39.3696 | M17: Levofloxacin | N17: 250 mg | O17: =O10 -> 0.02815 | P17: 4 | Q17: 30 | R17: 12 | S17: =P17*Q17*R17 -> 1440 | T17: =O17*S17 -> 40.536
B18: Ethionamide | C18: 250 mg | D18: =D11 -> 0.0793 | E18: 3 | F18: 30 | G18: 12 | H18: =E18*F18*G18 -> 1080 | I18: =D18*H18 -> 85.644 | M18: Ethionamide | N18: 250 mg | O18: =O11 -> 0.09688 | P18: 3 | Q18: 30 | R18: 12 | S18: =P18*Q18*R18 -> 1080 | T18: =O18*S18 -> 104.6304
B19: Cycloserine | C19: 250 mg | D19: =D12 -> 0.2594 | E19: 2 | F19: 30 | G19: 12 | H19: =E19*F19*G19 -> 720 | I19: =D19*H19 -> 186.768 | M19: Cycloserine | N19: 250 mg | O19: =O12 -> 0.2519 | P19: 2 | Q19: 30 | R19: 12 | S19: =P19*Q19*R19 -> 720 | T19: =O19*S19 -> 181.368
H20: Total Cost (USD) of Continuation Phase | I20: =SUM(I16:I19) -> 334.2456 | S20: Total Cost (USD) of Continuation Phase | T20: =SUM(T16:T19) -> 349.12851
H22: TOTAL COST PER PATIENT FOR 20 months: | I22: =I13+I20 -> 1353.132 | S22: TOTAL COST PER PATIENT FOR 20 months: | T22: =T13+T20 -> 1119.2409
B24: Updated Example of low end-of-range cost calculation for one country
B25: Treatment regimen 8 Am Eto Cs Lfx/ 16 Eto Cs Lfx
B26: December 2011 EXW manufacturers prices
B28: Intensive Phase
B29: Medicine | C29: Strength | D29: Cost per Basic Units of Consumption (BUC) | E29: Daily Dose in BUC | F29: Days in Months | G29: No. of months | H29: Full treatment in BUC / Number of BUC required | I29: Cost of Intensive Phase in US$
B30: Amikacin | C30: 500 mg | D30: =#REF! -> #REF! | E30: 2 | F30: 30 | G30: 8 | H30: =E30*F30*G30 -> 480 | I30: =D30*H30 -> #REF!
B31: Ethionamide | C31: 250 mg | D31: =#REF! -> #REF! | E31: 3 | F31: 30 | G31: 8 | H31: =E31*F31*G31 -> 720 | I31: =D31*H31 -> #REF!
B32: Cycloserin | C32: 250 mg | D32: =#REF! -> #REF! | E32: 3 | F32: 30 | G32: 8 | H32: =E32*F32*G32 -> 720 | I32: =D32*H32 -> #REF!
B33: Levofloxacin | C33: 250 mg | D33: =#REF! -> #REF! | E33: 3 | F33: 30 | G33: 8 | H33: =E33*F33*G33 -> 720 | I33: =D33*H33 -> #REF!
H34: Total Cost (USD) of Intensive Phase | I34: =SUM(I30:I33) -> #REF!
B35: Continuation Phase
B36: Medicine | C36: Strength | D36: Cost per Basic Units of Consumption (BUC) | E36: Daily Dose in BUC | F36: Days in Months | G36: No. of months | H36: Full treatment in BUC / Number of BUC required | I36: Cost of Intensive Phase in US$
B37: Ethionamide | C37: 250 mg | D37: =#REF! -> #REF! | E37: 3 | F37: 30 | G37: 16 | H37: =E37*F37*G37 -> 1440 | I37: =D37*H37 -> #REF!
B38: Cycloserin | C38: 250 mg | D38: =#REF! -> #REF! | E38: 3 | F38: 30 | G38: 16 | H38: =E38*F38*G38 -> 1440 | I38: =D38*H38 -> #REF!
B39: Levoxloxacin | C39: 250 mg | D39: =#REF! -> #REF! | E39: 3 | F39: 30 | G39: 16 | H39: =E39*F39*G39 -> 1440 | I39: =D39*H39 -> #REF!
H40: Total Cost (USD) of Intensive Phase | I40: =SUM(I37:I39) -> #REF!
H42: TOTAL COST PER PATIENT FOR 24 months: | I42: =I34+I40 -> #REF!
B44: Notes: - The Cost containtment examples of low and high range have been updated according to the current treatment regimens used by the programs. The length of the intensive and continuation phase have been modified and for the high range, Moxifloxacin has been chosen as floroquinalone and for the low range Amikacin has been seclected as injectable. - The treatment cost only include the cost EXW of the drugs, it does not include related costs such as procurement fee, quality control, consolidation, etc. It is estimated that those cost will represent 10% of the cost EXW of the drugs

Sheet Old LTR Cm Pto
B2: 2018 | M2: 2019
B3: Treatment regimen: 8 Z Cm Lfx Pto Cs WFI / 12 Z Lfx Pto Cs | M3: Treatment regimen: 8 Z Cm Lfx Eto Cs WFI / 12 Z Lfx Eto Cs
B4: 46-55 kg weight band | M4: 46-55 kg weight band
B6: Intensive Phase | M6: Intensive Phase
B7: Medicine | C7: Strength | D7: Cost per tablet/vial | E7: Daily Dose in tablet/vial | F7: Days in Months | G7: No. of months | H7: Full treatment / Number of tablet/vial required | I7: Cost of Intensive Phase in US$ | M7: Medicine | N7: Strength | O7: Cost per tablet/vial | P7: Daily Dose in tablet/vial | Q7: Days in Months | R7: No. of months | S7: Full treatment / Number of tablet/vial required | T7: Cost of Intensive Phase in US$
B8: Pyrazinamide | C8: 400mg | D8: 0.0208 | E8: 3 | F8: 30 | G8: 8 | H8: =E8*F8*G8 -> 720 | I8: =D8*H8 -> 14.976 | M8: Pyrazinamide | N8: 400mg | O8: 0.020920476 | P8: 3 | Q8: 30 | R8: 8 | S8: =P8*Q8*R8 -> 720 | T8: =O8*S8 -> 15.062743
